<?xml version="1.0"?>
<robot name="abot"
	xmlns:xacro="http://www.ros.org/wiki/xacro">
	<!-- Left wheel CAD link -->
	<link name="left_wheel1">
		<inertial>
			<origin xyz="-1.7545E-10 0.00056576 6.1245E-11" rpy="0 0 0" />
			<mass value="${wheel_mass}" />
			<inertia ixx="2.0701E-05" ixy="3.2217E-14" ixz="8.6674E-12" iyy="3.5827E-05" iyz="3.3202E-15" izz="2.0701E-05" />
		</inertial>
		<visual>
			<origin xyz="0 0 0" rpy="0 0 0" />
			<geometry>
				<mesh filename="package://abot_description/meshes/left_wheel.STL" />
			</geometry>
			<material name="Green" />
		</visual>
		<collision>
			<origin xyz="0 0 0" rpy="0 0 0" />
			<geometry>
				<mesh filename="package://abot_description/meshes/left_wheel.STL" />
			</geometry>
		</collision>
	</link>
	<!-- Left wheel geometry link-->
	<link name="left_wheel">
		<inertial>
			<origin xyz="-1.7545E-10 0.00056576 6.1245E-11" rpy="0 0 0" />
			<mass value="${wheel_mass}" />
			<xacro:cylinder_inertia mass="${wheel_mass}" radius="${wheel_radius}" height="${wheel_width}" />
		</inertial>
		<visual>
			<origin xyz="0 0 0" rpy="${PI/2} 0 0" />
			<geometry>
				<cylinder length="${wheel_width}" radius="${wheel_radius}" />
			</geometry>
			<material name="Green" />
		</visual>
		<collision>
			<origin xyz="0 0 0" rpy="${PI/2} 0 0" />
			<geometry>
				<cylinder length="${wheel_width}" radius="${wheel_radius}" />
			</geometry>
		</collision>
	</link>
	<!-- Left wheel joints -->
	<joint name="left_wheel_to_base" type="continuous">
		<origin xyz="0 0.0679999999999999 0.0145000000000007" rpy="0 0 0" />
		<parent link="abot_base" />
		<child link="left_wheel" />
		<axis xyz="0 1 0" />
	</joint>
	<joint name="left_wheel_to_wheel1" type="fixed">
		<parent link="left_wheel" />
		<child link="left_wheel1" />
		<origin xyz="0 0 0" rpy="0 0 0" />
	</joint>
</robot>
